2024-04-03 02:52:31,106 INFO    MainThread:3596 [wandb_setup.py:_flush():76] Current SDK version is 0.16.5
2024-04-03 02:52:31,106 INFO    MainThread:3596 [wandb_setup.py:_flush():76] Configure stats pid to 3596
2024-04-03 02:52:31,106 INFO    MainThread:3596 [wandb_setup.py:_flush():76] Loading settings from C:\Users\IamNa\.config\wandb\settings
2024-04-03 02:52:31,106 INFO    MainThread:3596 [wandb_setup.py:_flush():76] Loading settings from D:\Thesis\Pytorch-UNet-master\Pytorch-UNet-master\wandb\settings
2024-04-03 02:52:31,107 INFO    MainThread:3596 [wandb_setup.py:_flush():76] Loading settings from environment variables: {}
2024-04-03 02:52:31,107 INFO    MainThread:3596 [wandb_setup.py:_flush():76] Applying setup settings: {'_disable_service': False}
2024-04-03 02:52:31,108 INFO    MainThread:3596 [wandb_setup.py:_flush():76] Inferring run settings from compute environment: {'program_relpath': 'train.py', 'program_abspath': 'D:\\Thesis\\Pytorch-UNet-master\\Pytorch-UNet-master\\train.py', 'program': 'D:\\Thesis\\Pytorch-UNet-master\\Pytorch-UNet-master\\train.py'}
2024-04-03 02:52:31,108 INFO    MainThread:3596 [wandb_setup.py:_flush():76] Applying login settings: {'anonymous': 'must'}
2024-04-03 02:52:31,108 INFO    MainThread:3596 [wandb_init.py:_log_setup():527] Logging user logs to D:\Thesis\Pytorch-UNet-master\Pytorch-UNet-master\wandb\run-20240403_025231-3xjbyrug\logs\debug.log
2024-04-03 02:52:31,108 INFO    MainThread:3596 [wandb_init.py:_log_setup():528] Logging internal logs to D:\Thesis\Pytorch-UNet-master\Pytorch-UNet-master\wandb\run-20240403_025231-3xjbyrug\logs\debug-internal.log
2024-04-03 02:52:31,108 INFO    MainThread:3596 [wandb_init.py:init():567] calling init triggers
2024-04-03 02:52:31,108 INFO    MainThread:3596 [wandb_init.py:init():574] wandb.init called with sweep_config: {}
config: {}
2024-04-03 02:52:31,108 INFO    MainThread:3596 [wandb_init.py:init():617] starting backend
2024-04-03 02:52:31,108 INFO    MainThread:3596 [wandb_init.py:init():621] setting up manager
2024-04-03 02:52:31,110 INFO    MainThread:3596 [backend.py:_multiprocessing_setup():105] multiprocessing start_methods=spawn, using: spawn
2024-04-03 02:52:31,114 INFO    MainThread:3596 [wandb_init.py:init():629] backend started and connected
2024-04-03 02:52:31,118 INFO    MainThread:3596 [wandb_init.py:init():721] updated telemetry
2024-04-03 02:52:31,120 INFO    MainThread:3596 [wandb_init.py:init():754] communicating run to backend with 90.0 second timeout
2024-04-03 02:52:35,597 INFO    Thread-9 (wrapped_target):3596 [retry.py:__call__():172] Retry attempt failed:
Traceback (most recent call last):
  File "C:\Users\IamNa\AppData\Local\Programs\Python\Python312\Lib\site-packages\urllib3\connection.py", line 198, in _new_conn
    sock = connection.create_connection(
           ^^^^^^^^^^^^^^^^^^^^^^^^^^^^^
  File "C:\Users\IamNa\AppData\Local\Programs\Python\Python312\Lib\site-packages\urllib3\util\connection.py", line 85, in create_connection
    raise err
  File "C:\Users\IamNa\AppData\Local\Programs\Python\Python312\Lib\site-packages\urllib3\util\connection.py", line 73, in create_connection
    sock.connect(sa)
ConnectionRefusedError: [WinError 10061] No connection could be made because the target machine actively refused it

The above exception was the direct cause of the following exception:

Traceback (most recent call last):
  File "C:\Users\IamNa\AppData\Local\Programs\Python\Python312\Lib\site-packages\urllib3\connectionpool.py", line 779, in urlopen
    self._prepare_proxy(conn)
  File "C:\Users\IamNa\AppData\Local\Programs\Python\Python312\Lib\site-packages\urllib3\connectionpool.py", line 1048, in _prepare_proxy
    conn.connect()
  File "C:\Users\IamNa\AppData\Local\Programs\Python\Python312\Lib\site-packages\urllib3\connection.py", line 616, in connect
    self.sock = sock = self._new_conn()
                       ^^^^^^^^^^^^^^^^
  File "C:\Users\IamNa\AppData\Local\Programs\Python\Python312\Lib\site-packages\urllib3\connection.py", line 213, in _new_conn
    raise NewConnectionError(
urllib3.exceptions.NewConnectionError: <urllib3.connection.HTTPSConnection object at 0x0000017BAFC951F0>: Failed to establish a new connection: [WinError 10061] No connection could be made because the target machine actively refused it

The above exception was the direct cause of the following exception:

urllib3.exceptions.ProxyError: ('Unable to connect to proxy', NewConnectionError('<urllib3.connection.HTTPSConnection object at 0x0000017BAFC951F0>: Failed to establish a new connection: [WinError 10061] No connection could be made because the target machine actively refused it'))

The above exception was the direct cause of the following exception:

Traceback (most recent call last):
  File "C:\Users\IamNa\AppData\Local\Programs\Python\Python312\Lib\site-packages\requests\adapters.py", line 486, in send
    resp = conn.urlopen(
           ^^^^^^^^^^^^^
  File "C:\Users\IamNa\AppData\Local\Programs\Python\Python312\Lib\site-packages\urllib3\connectionpool.py", line 847, in urlopen
    retries = retries.increment(
              ^^^^^^^^^^^^^^^^^^
  File "C:\Users\IamNa\AppData\Local\Programs\Python\Python312\Lib\site-packages\urllib3\util\retry.py", line 515, in increment
    raise MaxRetryError(_pool, url, reason) from reason  # type: ignore[arg-type]
    ^^^^^^^^^^^^^^^^^^^^^^^^^^^^^^^^^^^^^^^^^^^^^^^^^^^
urllib3.exceptions.MaxRetryError: HTTPSConnectionPool(host='api.wandb.ai', port=443): Max retries exceeded with url: /graphql (Caused by ProxyError('Unable to connect to proxy', NewConnectionError('<urllib3.connection.HTTPSConnection object at 0x0000017BAFC951F0>: Failed to establish a new connection: [WinError 10061] No connection could be made because the target machine actively refused it')))

During handling of the above exception, another exception occurred:

Traceback (most recent call last):
  File "C:\Users\IamNa\AppData\Local\Programs\Python\Python312\Lib\site-packages\wandb\sdk\lib\retry.py", line 131, in __call__
    result = self._call_fn(*args, **kwargs)
             ^^^^^^^^^^^^^^^^^^^^^^^^^^^^^^
  File "C:\Users\IamNa\AppData\Local\Programs\Python\Python312\Lib\site-packages\wandb\sdk\internal\internal_api.py", line 369, in execute
    return self.client.execute(*args, **kwargs)  # type: ignore
           ^^^^^^^^^^^^^^^^^^^^^^^^^^^^^^^^^^^^
  File "C:\Users\IamNa\AppData\Local\Programs\Python\Python312\Lib\site-packages\wandb\vendor\gql-0.2.0\wandb_gql\client.py", line 52, in execute
    result = self._get_result(document, *args, **kwargs)
             ^^^^^^^^^^^^^^^^^^^^^^^^^^^^^^^^^^^^^^^^^^^
  File "C:\Users\IamNa\AppData\Local\Programs\Python\Python312\Lib\site-packages\wandb\vendor\gql-0.2.0\wandb_gql\client.py", line 60, in _get_result
    return self.transport.execute(document, *args, **kwargs)
           ^^^^^^^^^^^^^^^^^^^^^^^^^^^^^^^^^^^^^^^^^^^^^^^^^
  File "C:\Users\IamNa\AppData\Local\Programs\Python\Python312\Lib\site-packages\wandb\sdk\lib\gql_request.py", line 58, in execute
    request = self.session.post(self.url, **post_args)
              ^^^^^^^^^^^^^^^^^^^^^^^^^^^^^^^^^^^^^^^^
  File "C:\Users\IamNa\AppData\Local\Programs\Python\Python312\Lib\site-packages\requests\sessions.py", line 637, in post
    return self.request("POST", url, data=data, json=json, **kwargs)
           ^^^^^^^^^^^^^^^^^^^^^^^^^^^^^^^^^^^^^^^^^^^^^^^^^^^^^^^^^
  File "C:\Users\IamNa\AppData\Local\Programs\Python\Python312\Lib\site-packages\requests\sessions.py", line 589, in request
    resp = self.send(prep, **send_kwargs)
           ^^^^^^^^^^^^^^^^^^^^^^^^^^^^^^
  File "C:\Users\IamNa\AppData\Local\Programs\Python\Python312\Lib\site-packages\requests\sessions.py", line 703, in send
    r = adapter.send(request, **kwargs)
        ^^^^^^^^^^^^^^^^^^^^^^^^^^^^^^^
  File "C:\Users\IamNa\AppData\Local\Programs\Python\Python312\Lib\site-packages\requests\adapters.py", line 513, in send
    raise ProxyError(e, request=request)
requests.exceptions.ProxyError: HTTPSConnectionPool(host='api.wandb.ai', port=443): Max retries exceeded with url: /graphql (Caused by ProxyError('Unable to connect to proxy', NewConnectionError('<urllib3.connection.HTTPSConnection object at 0x0000017BAFC951F0>: Failed to establish a new connection: [WinError 10061] No connection could be made because the target machine actively refused it')))
2024-04-03 02:54:00,429 INFO    MainThread:3596 [wandb_run.py:_on_init():2344] communicating current version
2024-04-03 02:54:01,839 INFO    MainThread:3596 [wandb_run.py:_on_init():2353] got version response 
2024-04-03 02:54:01,840 INFO    MainThread:3596 [wandb_init.py:init():805] starting run threads in backend
2024-04-03 02:54:03,235 INFO    MainThread:3596 [wandb_run.py:_console_start():2323] atexit reg
2024-04-03 02:54:03,235 INFO    MainThread:3596 [wandb_run.py:_redirect():2178] redirect: wrap_raw
2024-04-03 02:54:03,235 INFO    MainThread:3596 [wandb_run.py:_redirect():2243] Wrapping output streams.
2024-04-03 02:54:03,235 INFO    MainThread:3596 [wandb_run.py:_redirect():2268] Redirects installed.
2024-04-03 02:54:03,236 INFO    MainThread:3596 [wandb_init.py:init():848] run started, returning control to user process
2024-04-03 02:54:03,237 INFO    MainThread:3596 [wandb_run.py:_config_callback():1347] config_cb None None {'epochs': 10, 'batch_size': 1, 'learning_rate': 1e-05, 'val_percent': 0.1, 'save_checkpoint': True, 'img_scale': 0.5, 'amp': False}
2024-04-03 02:54:40,429 WARNING MsgRouterThr:3596 [router.py:message_loop():77] message_loop has been closed
